<?xml version="1.0" ?>
<mujoco model="animat_0">
  <compiler boundmass="1.0000000000000001e-15" boundinertia="1.0000000000000001e-15" balanceinertia="false" angle="radian" eulerseq="xyz" discardvisual="false" fusestatic="true" inertiafromgeom="false">
    <lengthrange mode="none" useexisting="true"/>
  </compiler>
  <option timestep="0.0025000000000000001" gravity="0 0 -9.8100000000000005" impratio="10" integrator="implicitfast" cone="elliptic" solver="CG" iterations="1000" noslip_iterations="1000" noslip_tolerance="9.9999999999999995e-07" ccd_iterations="1000" ccd_tolerance="9.9999999999999995e-07">
    <flag energy="enable"/>
  </option>
  <size njmax="4096" nconmax="4096" nkey="1"/>
  <visual>
    <global offwidth="1280" offheight="720"/>
    <quality shadowsize="4096" offsamples="4" numslices="28" numstacks="16" numquads="4"/>
    <map stiffness="100" stiffnessrot="500" force="1" torque="1" alpha="0.29999999999999999" fogstart="3" fogend="10" znear="1.0000000000000001e-05" zfar="3" haze="0.29999999999999999" shadowclip="1" shadowscale="0.29999999999999999" actuatortendon="2"/>
    <scale forcewidth="0.01" contactwidth="0.029999999999999999" contactheight="0.01" connect="0.01" com="0.01" camera="0.10000000000000001" light="0.10000000000000001" selectpoint="0.01" jointlength="0.01" jointwidth="0.01" actuatorlength="0.01" actuatorwidth="0.01" framelength="0.01" framewidth="0.01" constraint="0.01" slidercrank="0.01"/>
  </visual>
  <statistic meanmass="1" meaninertia="1" meansize="1" extent="100"/>
  <default>
    <default class="/"/>
  </default>
  <asset>
    <texture name="texture_grid" type="2d" builtin="checker" rgb1="0.10000000000000001 0.20000000000000001 0.29999999999999999" rgb2="0.20000000000000001 0.29999999999999999 0.40000000000000002" mark="edge" markrgb="0.20000000000000001 0.29999999999999999 0.40000000000000002" width="300" height="300"/>
    <material name="material_grid" class="/" texture="texture_grid" texrepeat="1 1" texuniform="true" reflectance="0.20000000000000001"/>
    <mesh name="a0_mesh_link_body_00_collision" class="/" file="link_body_00_collision.stl" scale="0.001 0.001 0.001"/>
    <texture name="a0_texture_link_body_00_composite" type="2d" file="link_body_00_composite.png"/>
    <material name="a0_material_link_body_00_composite" class="/" texture="a0_texture_link_body_00_composite" specular="1" shininess="1"/>
    <mesh name="a0_mesh_link_body_00_visual" class="/" file="link_body_00_composite.obj" scale="0.001 0.001 0.001"/>
    <mesh name="a0_mesh_link_body_01_collision" class="/" file="link_body_01_collision.stl" scale="0.001 0.001 0.001"/>
    <texture name="a0_texture_link_body_01_composite" type="2d" file="link_body_01_composite.png"/>
    <material name="a0_material_link_body_01_composite" class="/" texture="a0_texture_link_body_01_composite" specular="1" shininess="1"/>
    <mesh name="a0_mesh_link_body_01_visual" class="/" file="link_body_01_composite.obj" scale="0.001 0.001 0.001"/>
    <mesh name="a0_mesh_link_body_02_collision" class="/" file="link_body_02_collision.stl" scale="0.001 0.001 0.001"/>
    <texture name="a0_texture_link_body_02_composite" type="2d" file="link_body_02_composite.png"/>
    <material name="a0_material_link_body_02_composite" class="/" texture="a0_texture_link_body_02_composite" specular="1" shininess="1"/>
    <mesh name="a0_mesh_link_body_02_visual" class="/" file="link_body_02_composite.obj" scale="0.001 0.001 0.001"/>
    <mesh name="a0_mesh_link_body_03_collision" class="/" file="link_body_03_collision.stl" scale="0.001 0.001 0.001"/>
    <texture name="a0_texture_link_body_03_composite" type="2d" file="link_body_03_composite.png"/>
    <material name="a0_material_link_body_03_composite" class="/" texture="a0_texture_link_body_03_composite" specular="1" shininess="1"/>
    <mesh name="a0_mesh_link_body_03_visual" class="/" file="link_body_03_composite.obj" scale="0.001 0.001 0.001"/>
    <mesh name="a0_mesh_link_body_04_collision" class="/" file="link_body_04_collision.stl" scale="0.001 0.001 0.001"/>
    <texture name="a0_texture_link_body_04_composite" type="2d" file="link_body_04_composite.png"/>
    <material name="a0_material_link_body_04_composite" class="/" texture="a0_texture_link_body_04_composite" specular="1" shininess="1"/>
    <mesh name="a0_mesh_link_body_04_visual" class="/" file="link_body_04_composite.obj" scale="0.001 0.001 0.001"/>
    <mesh name="a0_mesh_link_body_05_collision" class="/" file="link_body_05_collision.stl" scale="0.001 0.001 0.001"/>
    <texture name="a0_texture_link_body_05_composite" type="2d" file="link_body_05_composite.png"/>
    <material name="a0_material_link_body_05_composite" class="/" texture="a0_texture_link_body_05_composite" specular="1" shininess="1"/>
    <mesh name="a0_mesh_link_body_05_visual" class="/" file="link_body_05_composite.obj" scale="0.001 0.001 0.001"/>
    <mesh name="a0_mesh_link_body_06_collision" class="/" file="link_body_06_collision.stl" scale="0.001 0.001 0.001"/>
    <texture name="a0_texture_link_body_06_composite" type="2d" file="link_body_06_composite.png"/>
    <material name="a0_material_link_body_06_composite" class="/" texture="a0_texture_link_body_06_composite" specular="1" shininess="1"/>
    <mesh name="a0_mesh_link_body_06_visual" class="/" file="link_body_06_composite.obj" scale="0.001 0.001 0.001"/>
    <mesh name="a0_mesh_link_body_07_collision" class="/" file="link_body_07_collision.stl" scale="0.001 0.001 0.001"/>
    <texture name="a0_texture_link_body_07_composite" type="2d" file="link_body_07_composite.png"/>
    <material name="a0_material_link_body_07_composite" class="/" texture="a0_texture_link_body_07_composite" specular="1" shininess="1"/>
    <mesh name="a0_mesh_link_body_07_visual" class="/" file="link_body_07_composite.obj" scale="0.001 0.001 0.001"/>
    <mesh name="a0_mesh_link_body_08_collision" class="/" file="link_body_08_collision.stl" scale="0.001 0.001 0.001"/>
    <texture name="a0_texture_link_body_08_composite" type="2d" file="link_body_08_composite.png"/>
    <material name="a0_material_link_body_08_composite" class="/" texture="a0_texture_link_body_08_composite" specular="1" shininess="1"/>
    <mesh name="a0_mesh_link_body_08_visual" class="/" file="link_body_08_composite.obj" scale="0.001 0.001 0.001"/>
    <mesh name="a0_mesh_link_body_09_collision" class="/" file="link_body_09_collision.stl" scale="0.001 0.001 0.001"/>
    <texture name="a0_texture_link_body_09_composite" type="2d" file="link_body_09_composite.png"/>
    <material name="a0_material_link_body_09_composite" class="/" texture="a0_texture_link_body_09_composite" specular="1" shininess="1"/>
    <mesh name="a0_mesh_link_body_09_visual" class="/" file="link_body_09_composite.obj" scale="0.001 0.001 0.001"/>
    <mesh name="a0_mesh_link_body_10_collision" class="/" file="link_body_10_collision.stl" scale="0.001 0.001 0.001"/>
    <mesh name="a0_mesh_link_body_10_visual" class="/" file="link_body_10_composite.obj" scale="0.001 0.001 0.001"/>
    <mesh name="a0_mesh_link_leg_1_L_0_collision" class="/" file="link_leg_1_L_0_collision.stl" scale="0.001 0.001 0.001"/>
    <texture name="a0_texture_link_leg_1_L_0_composite" type="2d" file="link_leg_1_L_0_composite.png"/>
    <material name="a0_material_link_leg_1_L_0_composite" class="/" texture="a0_texture_link_leg_1_L_0_composite" specular="1" shininess="1"/>
    <mesh name="a0_mesh_link_leg_1_L_0_visual" class="/" file="link_leg_1_L_0_composite.obj" scale="0.001 0.001 0.001"/>
    <mesh name="a0_mesh_link_leg_1_L_1_collision" class="/" file="link_leg_1_L_1_collision.stl" scale="0.001 0.001 0.001"/>
    <texture name="a0_texture_link_leg_1_L_1_composite" type="2d" file="link_leg_1_L_1_composite.png"/>
    <material name="a0_material_link_leg_1_L_1_composite" class="/" texture="a0_texture_link_leg_1_L_1_composite" specular="1" shininess="1"/>
    <mesh name="a0_mesh_link_leg_1_L_1_visual" class="/" file="link_leg_1_L_1_composite.obj" scale="0.001 0.001 0.001"/>
    <mesh name="a0_mesh_link_leg_1_R_0_collision" class="/" file="link_leg_1_R_0_collision.stl" scale="0.001 0.001 0.001"/>
    <texture name="a0_texture_link_leg_1_R_0_composite" type="2d" file="link_leg_1_R_0_composite.png"/>
    <material name="a0_material_link_leg_1_R_0_composite" class="/" texture="a0_texture_link_leg_1_R_0_composite" specular="1" shininess="1"/>
    <mesh name="a0_mesh_link_leg_1_R_0_visual" class="/" file="link_leg_1_R_0_composite.obj" scale="0.001 0.001 0.001"/>
    <mesh name="a0_mesh_link_leg_1_R_1_collision" class="/" file="link_leg_1_R_1_collision.stl" scale="0.001 0.001 0.001"/>
    <texture name="a0_texture_link_leg_1_R_1_composite" type="2d" file="link_leg_1_R_1_composite.png"/>
    <material name="a0_material_link_leg_1_R_1_composite" class="/" texture="a0_texture_link_leg_1_R_1_composite" specular="1" shininess="1"/>
    <mesh name="a0_mesh_link_leg_1_R_1_visual" class="/" file="link_leg_1_R_1_composite.obj" scale="0.001 0.001 0.001"/>
    <mesh name="a0_mesh_link_leg_0_L_0_collision" class="/" file="link_leg_0_L_0_collision.stl" scale="0.001 0.001 0.001"/>
    <texture name="a0_texture_link_leg_0_L_0_composite" type="2d" file="link_leg_0_L_0_composite.png"/>
    <material name="a0_material_link_leg_0_L_0_composite" class="/" texture="a0_texture_link_leg_0_L_0_composite" specular="1" shininess="1"/>
    <mesh name="a0_mesh_link_leg_0_L_0_visual" class="/" file="link_leg_0_L_0_composite.obj" scale="0.001 0.001 0.001"/>
    <mesh name="a0_mesh_link_leg_0_L_1_collision" class="/" file="link_leg_0_L_1_collision.stl" scale="0.001 0.001 0.001"/>
    <texture name="a0_texture_link_leg_0_L_1_composite" type="2d" file="link_leg_0_L_1_composite.png"/>
    <material name="a0_material_link_leg_0_L_1_composite" class="/" texture="a0_texture_link_leg_0_L_1_composite" specular="1" shininess="1"/>
    <mesh name="a0_mesh_link_leg_0_L_1_visual" class="/" file="link_leg_0_L_1_composite.obj" scale="0.001 0.001 0.001"/>
    <mesh name="a0_mesh_link_leg_0_R_0_collision" class="/" file="link_leg_0_R_0_collision.stl" scale="0.001 0.001 0.001"/>
    <texture name="a0_texture_link_leg_0_R_0_composite" type="2d" file="link_leg_0_R_0_composite.png"/>
    <material name="a0_material_link_leg_0_R_0_composite" class="/" texture="a0_texture_link_leg_0_R_0_composite" specular="1" shininess="1"/>
    <mesh name="a0_mesh_link_leg_0_R_0_visual" class="/" file="link_leg_0_R_0_composite.obj" scale="0.001 0.001 0.001"/>
    <mesh name="a0_mesh_link_leg_0_R_1_collision" class="/" file="link_leg_0_R_1_collision.stl" scale="0.001 0.001 0.001"/>
    <texture name="a0_texture_link_leg_0_R_1_composite" type="2d" file="link_leg_0_R_1_composite.png"/>
    <material name="a0_material_link_leg_0_R_1_composite" class="/" texture="a0_texture_link_leg_0_R_1_composite" specular="1" shininess="1"/>
    <mesh name="a0_mesh_link_leg_0_R_1_visual" class="/" file="link_leg_0_R_1_composite.obj" scale="0.001 0.001 0.001"/>
    <texture name="skybox" type="skybox" builtin="gradient" rgb1="0.40000000000000002 0.59999999999999998 0.80000000000000004" rgb2="0 0 0" mark="random" markrgb="1 1 1" width="800" height="800"/>
  </asset>
  <worldbody>
    <body name="arena_flat" pos="0 0 0" quat="1 0 0 0">
      <body name="floor" pos="0 0 0" quat="1 0 0 0">
        <geom name="floor_collision" class="/" type="plane" contype="1" conaffinity="61" condim="6" group="2" size="100 100 1" material="material_grid" friction="0 0 0" margin="0" pos="0 0 0" quat="1 0 0 0"/>
        <geom name="floor_visual" class="/" type="plane" contype="0" conaffinity="0" group="1" size="100 100 1" material="material_grid" pos="0 0 0" quat="1 0 0 0"/>
      </body>
    </body>
    <body name="a0_Polymander_v6.2.1" pos="0 0 0.10000000000000001" quat="0.70710678118654757 0 0 0.70710678118654746">
      <freejoint name="a0_root_Polymander_v6.2.1"/>
      <body name="a0_link_body_00" pos="0 0 0" quat="1 0 0 0">
        <geom name="a0_link_body_00_collision" class="/" type="mesh" contype="2" conaffinity="61" condim="6" group="2" friction="0.29999999999999999 0 0" solref="0.01 1" solimp="0 0.94999999999999996 0.01 0.5 2" margin="0" pos="0 0 0" quat="1 0 0 0" mesh="a0_mesh_link_body_00_collision" fluidcoef="0 0 0 0 0"/>
        <geom name="a0_link_body_00_visual" class="/" type="mesh" contype="0" conaffinity="0" group="1" material="a0_material_link_body_00_composite" pos="0 0 0" quat="1 0 0 0" mesh="a0_mesh_link_body_00_visual"/>
        <inertial pos="0.087455599999999994 0.0011810499999999999 0.00195082" mass="0.328768" fullinertia="0.00013479799999999999 0.00063606899999999996 0.00060921300000000005 7.4325000000000004e-07 1.2197900000000001e-05 6.57418e-06"/>
        <body name="a0_link_body_01" pos="0.14646400000000001 0 -0.00025000000000000001" quat="1 0 0 0">
          <joint name="a0_joint_body_00" class="/" type="hinge" pos="0 0 0" axis="0 0 1" limited="true" stiffness="0.02" range="-1.5708 1.5708" springref="0" damping="0.5" frictionloss="0"/>
          <geom name="a0_link_body_01_collision" class="/" type="mesh" contype="2" conaffinity="61" condim="6" group="2" friction="0.29999999999999999 0 0" solref="0.01 1" solimp="0 0.94999999999999996 0.01 0.5 2" margin="0" pos="0 0 0" quat="1 0 0 0" mesh="a0_mesh_link_body_01_collision" fluidcoef="0 0 0 0 0"/>
          <geom name="a0_link_body_01_visual" class="/" type="mesh" contype="0" conaffinity="0" group="1" material="a0_material_link_body_01_composite" pos="0 0 0" quat="1 0 0 0" mesh="a0_mesh_link_body_01_visual"/>
          <inertial pos="0.057489699999999998 9.6835800000000002e-07 0.000163447" mass="0.27410099999999998" fullinertia="0.00019462799999999999 0.00011846 0.00022647499999999999 -8.1280999999999998e-11 -6.2000900000000003e-07 4.3554799999999999e-11"/>
          <body name="a0_link_body_02" pos="0.11529999999999999 0 0" quat="1 0 0 0">
            <joint name="a0_joint_body_01" class="/" type="hinge" pos="0 0 0" axis="0 0 1" limited="true" stiffness="0.018571428571428572" range="-1.5708 1.5708" springref="0" damping="0.5" frictionloss="0"/>
            <geom name="a0_link_body_02_collision" class="/" type="mesh" contype="2" conaffinity="61" condim="6" group="2" friction="0.29999999999999999 0 0" solref="0.01 1" solimp="0 0.94999999999999996 0.01 0.5 2" margin="0" pos="0 0 0" quat="1 0 0 0" mesh="a0_mesh_link_body_02_collision" fluidcoef="0 0 0 0 0"/>
            <geom name="a0_link_body_02_visual" class="/" type="mesh" contype="0" conaffinity="0" group="1" material="a0_material_link_body_02_composite" pos="0 0 0" quat="1 0 0 0" mesh="a0_mesh_link_body_02_visual"/>
            <inertial pos="0.0190111 2.1088299999999999e-11 -0.00041290499999999998" mass="0.10768800000000001" fullinertia="2.18349e-05 5.2095600000000003e-05 4.4087600000000001e-05 -2.87156e-14 -3.3164999999999998e-07 -3.0905300000000002e-12"/>
            <body name="a0_link_body_03" pos="0.068599999999999994 0 0" quat="1 0 0 0">
              <joint name="a0_joint_body_02" class="/" type="hinge" pos="0 0 0" axis="0 0 1" limited="true" stiffness="0.017142857142857144" range="-1.5708 1.5708" springref="0" damping="0.5" frictionloss="0"/>
              <geom name="a0_link_body_03_collision" class="/" type="mesh" contype="2" conaffinity="61" condim="6" group="2" friction="0.29999999999999999 0 0" solref="0.01 1" solimp="0 0.94999999999999996 0.01 0.5 2" margin="0" pos="0 0 0" quat="1 0 0 0" mesh="a0_mesh_link_body_03_collision" fluidcoef="0 0 0 0 0"/>
              <geom name="a0_link_body_03_visual" class="/" type="mesh" contype="0" conaffinity="0" group="1" material="a0_material_link_body_03_composite" pos="0 0 0" quat="1 0 0 0" mesh="a0_mesh_link_body_03_visual"/>
              <inertial pos="0.0190111 2.1088299999999999e-11 -0.00041290499999999998" mass="0.10768800000000001" fullinertia="2.18349e-05 5.2095600000000003e-05 4.4087600000000001e-05 -2.87156e-14 -3.3164999999999998e-07 -3.0905300000000002e-12"/>
              <body name="a0_link_body_04" pos="0.068599999999999994 0 0" quat="1 0 0 0">
                <joint name="a0_joint_body_03" class="/" type="hinge" pos="0 0 0" axis="0 0 1" limited="true" stiffness="0.015714285714285715" range="-1.5708 1.5708" springref="0" damping="0.5" frictionloss="0"/>
                <geom name="a0_link_body_04_collision" class="/" type="mesh" contype="2" conaffinity="61" condim="6" group="2" friction="0.29999999999999999 0 0" solref="0.01 1" solimp="0 0.94999999999999996 0.01 0.5 2" margin="0" pos="0 0 0" quat="1 0 0 0" mesh="a0_mesh_link_body_04_collision" fluidcoef="0 0 0 0 0"/>
                <geom name="a0_link_body_04_visual" class="/" type="mesh" contype="0" conaffinity="0" group="1" material="a0_material_link_body_04_composite" pos="0 0 0" quat="1 0 0 0" mesh="a0_mesh_link_body_04_visual"/>
                <inertial pos="0.0190111 2.1088299999999999e-11 -0.00041290499999999998" mass="0.10768800000000001" fullinertia="2.18349e-05 5.2095600000000003e-05 4.4087600000000001e-05 -2.87156e-14 -3.3164999999999998e-07 -3.0905300000000002e-12"/>
                <body name="a0_link_body_05" pos="0.068599999999999994 0 0" quat="1 0 0 0">
                  <joint name="a0_joint_body_04" class="/" type="hinge" pos="0 0 0" axis="0 0 1" limited="true" stiffness="0.014285714285714287" range="-1.5708 1.5708" springref="0" damping="0.5" frictionloss="0"/>
                  <geom name="a0_link_body_05_collision" class="/" type="mesh" contype="2" conaffinity="61" condim="6" group="2" friction="0.29999999999999999 0 0" solref="0.01 1" solimp="0 0.94999999999999996 0.01 0.5 2" margin="0" pos="0 0 0" quat="1 0 0 0" mesh="a0_mesh_link_body_05_collision" fluidcoef="0 0 0 0 0"/>
                  <geom name="a0_link_body_05_visual" class="/" type="mesh" contype="0" conaffinity="0" group="1" material="a0_material_link_body_05_composite" pos="0 0 0" quat="1 0 0 0" mesh="a0_mesh_link_body_05_visual"/>
                  <inertial pos="0.049430300000000003 -4.5481599999999997e-06 -8.1953200000000007e-05" mass="0.32161400000000001" fullinertia="0.000195584 0.000245362 0.000358215 2.2802999999999999e-08 -1.36018e-06 1.9728300000000001e-09"/>
                  <body name="a0_link_body_06" pos="0.085799999999999987 0 0" quat="1 0 0 0">
                    <joint name="a0_joint_body_05_passive" class="/" type="hinge" pos="0 0 0" axis="0 1 0" limited="true" stiffness="0.01" range="-0.40142600000000001 0.40142600000000001" springref="0" damping="0.001" frictionloss="0"/>
                    <geom name="a0_link_body_06_collision" class="/" type="mesh" contype="2" conaffinity="61" condim="6" group="2" friction="0.29999999999999999 0 0" solref="0.01 1" solimp="0 0.94999999999999996 0.01 0.5 2" margin="0" pos="0 0 0" quat="1 0 0 0" mesh="a0_mesh_link_body_06_collision" fluidcoef="0 0 0 0 0"/>
                    <geom name="a0_link_body_06_visual" class="/" type="mesh" contype="0" conaffinity="0" group="1" material="a0_material_link_body_06_composite" pos="0 0 0" quat="1 0 0 0" mesh="a0_mesh_link_body_06_visual"/>
                    <inertial pos="0.017175300000000001 5.6835600000000001e-11 0.00017922399999999999" mass="0.0433459" fullinertia="1.1253199999999999e-05 1.36167e-05 8.2754799999999992e-06 1.8402200000000001e-14 1.42377e-08 -3.0870499999999999e-12"/>
                    <body name="a0_link_body_07" pos="0.047399999999999998 0 0" quat="1 0 0 0">
                      <joint name="a0_joint_body_06" class="/" type="hinge" pos="0 0 0" axis="0 0 1" limited="true" stiffness="0.012857142857142859" range="-1.5708 1.5708" springref="0" damping="0.5" frictionloss="0"/>
                      <geom name="a0_link_body_07_collision" class="/" type="mesh" contype="2" conaffinity="61" condim="6" group="2" friction="0.29999999999999999 0 0" solref="0.01 1" solimp="0 0.94999999999999996 0.01 0.5 2" margin="0" pos="0 0 0" quat="1 0 0 0" mesh="a0_mesh_link_body_07_collision" fluidcoef="0 0 0 0 0"/>
                      <geom name="a0_link_body_07_visual" class="/" type="mesh" contype="0" conaffinity="0" group="1" material="a0_material_link_body_07_composite" pos="0 0 0" quat="1 0 0 0" mesh="a0_mesh_link_body_07_visual"/>
                      <inertial pos="0.0190111 2.1088299999999999e-11 -0.00041290499999999998" mass="0.10768800000000001" fullinertia="2.18349e-05 5.2095600000000003e-05 4.4087600000000001e-05 -2.87156e-14 -3.3164999999999998e-07 -3.0905300000000002e-12"/>
                      <body name="a0_link_body_08" pos="0.068599999999999994 0 0" quat="1 0 0 0">
                        <joint name="a0_joint_body_07" class="/" type="hinge" pos="0 0 0" axis="0 0 1" limited="true" stiffness="0.011428571428571429" range="-1.5708 1.5708" springref="0" damping="0.5" frictionloss="0"/>
                        <geom name="a0_link_body_08_collision" class="/" type="mesh" contype="2" conaffinity="61" condim="6" group="2" friction="0.29999999999999999 0 0" solref="0.01 1" solimp="0 0.94999999999999996 0.01 0.5 2" margin="0" pos="0 0 0" quat="1 0 0 0" mesh="a0_mesh_link_body_08_collision" fluidcoef="0 0 0 0 0"/>
                        <geom name="a0_link_body_08_visual" class="/" type="mesh" contype="0" conaffinity="0" group="1" material="a0_material_link_body_08_composite" pos="0 0 0" quat="1 0 0 0" mesh="a0_mesh_link_body_08_visual"/>
                        <inertial pos="0.0190111 2.1088299999999999e-11 -0.00041290499999999998" mass="0.10768800000000001" fullinertia="2.18349e-05 5.2095600000000003e-05 4.4087600000000001e-05 -2.87156e-14 -3.3164999999999998e-07 -3.0905300000000002e-12"/>
                        <body name="a0_link_body_09" pos="0.068601000000000023 0 0" quat="1 0 0 0">
                          <joint name="a0_joint_body_08" class="/" type="hinge" pos="0 0 0" axis="0 0 1" limited="true" stiffness="0.01" range="-1.5708 1.5708" springref="0" damping="0.5" frictionloss="0"/>
                          <geom name="a0_link_body_09_collision" class="/" type="mesh" contype="2" conaffinity="61" condim="6" group="2" friction="0.29999999999999999 0 0" solref="0.01 1" solimp="0 0.94999999999999996 0.01 0.5 2" margin="0" pos="0 0 0" quat="1 0 0 0" mesh="a0_mesh_link_body_09_collision" fluidcoef="0 0 0 0 0"/>
                          <geom name="a0_link_body_09_visual" class="/" type="mesh" contype="0" conaffinity="0" group="1" material="a0_material_link_body_09_composite" pos="0 0 0" quat="1 0 0 0" mesh="a0_mesh_link_body_09_visual"/>
                          <inertial pos="0.028998099999999999 5.5101500000000001e-05 -0.00025985800000000002" mass="0.16465099999999999" fullinertia="5.36951e-05 0.000114635 9.6605899999999996e-05 -1.3171200000000001e-07 -7.1426000000000004e-07 2.5572999999999997e-07"/>
                          <body name="a0_link_body_10" pos="0.068250000000000033 0 0" quat="1 0 0 0">
                            <joint name="a0_joint_body_09_passive" class="/" type="hinge" pos="0 0 0" axis="0 1 0" limited="true" stiffness="0.01" range="-0.40142600000000001 0.40142600000000001" springref="0" damping="0.001" frictionloss="0"/>
                            <geom name="a0_link_body_10_collision" class="/" type="mesh" contype="2" conaffinity="61" condim="6" group="2" friction="0.29999999999999999 0 0" solref="0.01 1" solimp="0 0.94999999999999996 0.01 0.5 2" margin="0" pos="0 0 0" quat="1 0 0 0" mesh="a0_mesh_link_body_10_collision" fluidcoef="0 0 0 0 0"/>
                            <geom name="a0_link_body_10_visual" class="/" type="mesh" contype="0" conaffinity="0" group="1" pos="0 0 0" quat="1 0 0 0" mesh="a0_mesh_link_body_10_visual"/>
                            <inertial pos="0.110208 1.5281299999999999e-11 -0.00024783699999999999" mass="0.18959000000000001" fullinertia="3.5034099999999997e-05 0.0012225999999999999 0.00119837 8.3813299999999997e-14 1.43151e-05 2.6169499999999998e-13"/>
                          </body>
                        </body>
                      </body>
                    </body>
                  </body>
                  <body name="a0_link_leg_1_L_0" pos="0.065050000000000052 -0.037999999999999999 0" quat="1 0 0 0">
                    <joint name="a0_joint_leg_1_L_0" class="/" type="hinge" pos="0 0 0" axis="0 0 -1" limited="true" stiffness="0.0030000000000000001" range="-1.2740899999999999 1.2740899999999999" springref="0" damping="0.10000000000000001" frictionloss="0"/>
                    <geom name="a0_link_leg_1_L_0_collision" class="/" type="mesh" contype="2" conaffinity="61" condim="6" group="2" friction="0.29999999999999999 0 0" solref="0.01 1" solimp="0 0.94999999999999996 0.01 0.5 2" margin="0" pos="0 0 0" quat="1 0 0 0" mesh="a0_mesh_link_leg_1_L_0_collision" fluidcoef="0 0 0 0 0"/>
                    <geom name="a0_link_leg_1_L_0_visual" class="/" type="mesh" contype="0" conaffinity="0" group="1" material="a0_material_link_leg_1_L_0_composite" pos="0 0 0" quat="1 0 0 0" mesh="a0_mesh_link_leg_1_L_0_visual"/>
                    <inertial pos="-0.0014378100000000001 -0.0216908 -0.0018551799999999999" mass="0.019448199999999999" fullinertia="9.5351699999999994e-06 8.3448100000000008e-06 9.2057299999999994e-06 -5.7539399999999997e-07 -2.4921699999999997e-07 -2.1006299999999998e-06"/>
                    <body name="a0_link_leg_1_L_1" pos="0 -0.041500000000000002 -0.01" quat="1 0 0 0">
                      <joint name="a0_joint_leg_1_L_1" class="/" type="hinge" pos="0 0 0" axis="1 0 0" limited="true" stiffness="0.10000000000000001" range="-1.25664 1.8326" springref="0" damping="0.29999999999999999" frictionloss="0"/>
                      <geom name="a0_link_leg_1_L_1_collision" class="/" type="mesh" contype="2" conaffinity="61" condim="6" group="2" friction="0.69999999999999996 0 0" solref="0.01 1" solimp="0 0.94999999999999996 0.01 0.5 2" margin="0" pos="0 0 0" quat="1 0 0 0" mesh="a0_mesh_link_leg_1_L_1_collision" fluidcoef="0 0 0 0 0"/>
                      <geom name="a0_link_leg_1_L_1_visual" class="/" type="mesh" contype="0" conaffinity="0" group="1" material="a0_material_link_leg_1_L_1_composite" pos="0 0 0" quat="1 0 0 0" mesh="a0_mesh_link_leg_1_L_1_visual"/>
                      <inertial pos="0.00031135499999999998 -0.035873299999999997 -0.0017959300000000001" mass="0.16436400000000001" fullinertia="0.000201757 5.0420999999999997e-05 0.000195818 -7.4662800000000001e-07 -4.2246699999999998e-08 -1.9949399999999999e-05"/>
                    </body>
                  </body>
                  <body name="a0_link_leg_1_R_0" pos="0.065050000000000052 0.037999999999999999 0" quat="1 0 0 0">
                    <joint name="a0_joint_leg_1_R_0" class="/" type="hinge" pos="0 0 0" axis="0 0 1" limited="true" stiffness="0.0030000000000000001" range="-1.2740899999999999 1.2740899999999999" springref="0" damping="0.10000000000000001" frictionloss="0"/>
                    <geom name="a0_link_leg_1_R_0_collision" class="/" type="mesh" contype="2" conaffinity="61" condim="6" group="2" friction="0.29999999999999999 0 0" solref="0.01 1" solimp="0 0.94999999999999996 0.01 0.5 2" margin="0" pos="0 0 0" quat="1 0 0 0" mesh="a0_mesh_link_leg_1_R_0_collision" fluidcoef="0 0 0 0 0"/>
                    <geom name="a0_link_leg_1_R_0_visual" class="/" type="mesh" contype="0" conaffinity="0" group="1" material="a0_material_link_leg_1_R_0_composite" pos="0 0 0" quat="1 0 0 0" mesh="a0_mesh_link_leg_1_R_0_visual"/>
                    <inertial pos="0.0014378100000000001 0.0216908 -0.0018551799999999999" mass="0.019448199999999999" fullinertia="9.5351699999999994e-06 8.3448100000000008e-06 9.2057299999999994e-06 -5.7539099999999999e-07 2.49214e-07 2.1006400000000001e-06"/>
                    <body name="a0_link_leg_1_R_1" pos="0 0.041500000000000002 -0.01" quat="1 0 0 0">
                      <joint name="a0_joint_leg_1_R_1" class="/" type="hinge" pos="0 0 0" axis="-1 0 0" limited="true" stiffness="0.10000000000000001" range="-1.25664 1.8326" springref="0" damping="0.29999999999999999" frictionloss="0"/>
                      <geom name="a0_link_leg_1_R_1_collision" class="/" type="mesh" contype="2" conaffinity="61" condim="6" group="2" friction="0.69999999999999996 0 0" solref="0.01 1" solimp="0 0.94999999999999996 0.01 0.5 2" margin="0" pos="0 0 0" quat="1 0 0 0" mesh="a0_mesh_link_leg_1_R_1_collision" fluidcoef="0 0 0 0 0"/>
                      <geom name="a0_link_leg_1_R_1_visual" class="/" type="mesh" contype="0" conaffinity="0" group="1" material="a0_material_link_leg_1_R_1_composite" pos="0 0 0" quat="1 0 0 0" mesh="a0_mesh_link_leg_1_R_1_visual"/>
                      <inertial pos="-0.00023358999999999999 0.035873299999999997 -0.0018034699999999999" mass="0.16436400000000001" fullinertia="0.00020177699999999999 5.0447800000000002e-05 0.000195825 -1.41312e-06 1.44843e-07 2.0009799999999999e-05"/>
                    </body>
                  </body>
                </body>
              </body>
            </body>
          </body>
          <body name="a0_link_leg_0_L_0" pos="0.057649999999999979 -0.037999999999999999 0" quat="1 0 0 0">
            <joint name="a0_joint_leg_0_L_0" class="/" type="hinge" pos="0 0 0" axis="0 0 -1" limited="true" stiffness="0.0030000000000000001" range="-1.2740899999999999 1.2740899999999999" springref="0" damping="0.10000000000000001" frictionloss="0"/>
            <geom name="a0_link_leg_0_L_0_collision" class="/" type="mesh" contype="2" conaffinity="61" condim="6" group="2" friction="0.29999999999999999 0 0" solref="0.01 1" solimp="0 0.94999999999999996 0.01 0.5 2" margin="0" pos="0 0 0" quat="1 0 0 0" mesh="a0_mesh_link_leg_0_L_0_collision" fluidcoef="0 0 0 0 0"/>
            <geom name="a0_link_leg_0_L_0_visual" class="/" type="mesh" contype="0" conaffinity="0" group="1" material="a0_material_link_leg_0_L_0_composite" pos="0 0 0" quat="1 0 0 0" mesh="a0_mesh_link_leg_0_L_0_visual"/>
            <inertial pos="-0.0014378100000000001 -0.0216908 -0.0018551799999999999" mass="0.019448199999999999" fullinertia="9.5351699999999994e-06 8.3448100000000008e-06 9.2057299999999994e-06 -5.7539399999999997e-07 -2.4921500000000003e-07 -2.1006299999999998e-06"/>
            <body name="a0_link_leg_0_L_1" pos="0 -0.041500000000000002 -0.01" quat="1 0 0 0">
              <joint name="a0_joint_leg_0_L_1" class="/" type="hinge" pos="0 0 0" axis="1 0 0" limited="true" stiffness="0.10000000000000001" range="-1.25664 1.8326" springref="0" damping="0.29999999999999999" frictionloss="0"/>
              <geom name="a0_link_leg_0_L_1_collision" class="/" type="mesh" contype="2" conaffinity="61" condim="6" group="2" friction="0.90000000000000002 0 0" solref="0.01 1" solimp="0 0.94999999999999996 0.01 0.5 2" margin="0" pos="0 0 0" quat="1 0 0 0" mesh="a0_mesh_link_leg_0_L_1_collision" fluidcoef="0 0 0 0 0"/>
              <geom name="a0_link_leg_0_L_1_visual" class="/" type="mesh" contype="0" conaffinity="0" group="1" material="a0_material_link_leg_0_L_1_composite" pos="0 0 0" quat="1 0 0 0" mesh="a0_mesh_link_leg_0_L_1_visual"/>
              <inertial pos="0.00027137400000000001 -0.035990800000000003 -0.0018395499999999999" mass="0.16436400000000001" fullinertia="0.00020175999999999999 5.0539299999999999e-05 0.00019569699999999999 -1.05974e-06 -6.4582800000000006e-08 -2.0094200000000002e-05"/>
            </body>
          </body>
          <body name="a0_link_leg_0_R_0" pos="0.057649999999999979 0.037999999999999999 0" quat="1 0 0 0">
            <joint name="a0_joint_leg_0_R_0" class="/" type="hinge" pos="0 0 0" axis="0 0 1" limited="true" stiffness="0.0030000000000000001" range="-1.2740899999999999 1.2740899999999999" springref="0" damping="0.10000000000000001" frictionloss="0"/>
            <geom name="a0_link_leg_0_R_0_collision" class="/" type="mesh" contype="2" conaffinity="61" condim="6" group="2" friction="0.29999999999999999 0 0" solref="0.01 1" solimp="0 0.94999999999999996 0.01 0.5 2" margin="0" pos="0 0 0" quat="1 0 0 0" mesh="a0_mesh_link_leg_0_R_0_collision" fluidcoef="0 0 0 0 0"/>
            <geom name="a0_link_leg_0_R_0_visual" class="/" type="mesh" contype="0" conaffinity="0" group="1" material="a0_material_link_leg_0_R_0_composite" pos="0 0 0" quat="1 0 0 0" mesh="a0_mesh_link_leg_0_R_0_visual"/>
            <inertial pos="0.0014378100000000001 0.0216908 -0.0018551799999999999" mass="0.019448199999999999" fullinertia="9.5351699999999994e-06 8.3448100000000008e-06 9.2057299999999994e-06 -5.7539099999999999e-07 2.49214e-07 2.1006400000000001e-06"/>
            <body name="a0_link_leg_0_R_1" pos="0 0.041500000000000002 -0.01" quat="1 0 0 0">
              <joint name="a0_joint_leg_0_R_1" class="/" type="hinge" pos="0 0 0" axis="-1 0 0" limited="true" stiffness="0.10000000000000001" range="-1.25664 1.8326" springref="0" damping="0.29999999999999999" frictionloss="0"/>
              <geom name="a0_link_leg_0_R_1_collision" class="/" type="mesh" contype="2" conaffinity="61" condim="6" group="2" friction="0.90000000000000002 0 0" solref="0.01 1" solimp="0 0.94999999999999996 0.01 0.5 2" margin="0" pos="0 0 0" quat="1 0 0 0" mesh="a0_mesh_link_leg_0_R_1_collision" fluidcoef="0 0 0 0 0"/>
              <geom name="a0_link_leg_0_R_1_visual" class="/" type="mesh" contype="0" conaffinity="0" group="1" material="a0_material_link_leg_0_R_1_composite" pos="0 0 0" quat="1 0 0 0" mesh="a0_mesh_link_leg_0_R_1_visual"/>
              <inertial pos="-0.00027137400000000001 0.035990800000000003 -0.0018395499999999999" mass="0.16436400000000001" fullinertia="0.00020175999999999999 5.0539299999999999e-05 0.00019569699999999999 -1.05974e-06 6.4582800000000006e-08 2.0094200000000002e-05"/>
            </body>
          </body>
        </body>
      </body>
      <light name="light_animat" class="/" mode="trackcom" directional="false" castshadow="true" active="true" pos="0.99999999999999978 1.0000000000000002 3" dir="-0.99999999999999978 -1.0000000000000002 -3" attenuation="1 0 0" cutoff="1000" exponent="1" ambient="0 0 0" diffuse="0.69999999999999996 0.69999999999999996 0.69999999999999996" specular="0.29999999999999999 0.29999999999999999 0.29999999999999999"/>
      <camera name="camera_a0_Polymander_v6.2.1_0" class="/" mode="trackcom" fovy="70" ipd="0.068000000000000005" pos="0 0 3" quat="0.70710678118654757 0 0 -0.70710678118654746"/>
      <camera name="camera_a0_Polymander_v6.2.1_1" class="/" mode="trackcom" fovy="70" ipd="0.068000000000000005" pos="-3 -6.6613381477509392e-16 0.60000000000000009" quat="0.57206140281768436 0.41562693777745346 -0.41562693777745341 -0.57206140281768425"/>
      <camera name="camera_a0_Polymander_v6.2.1_2" class="/" mode="trackcom" fovy="70" ipd="0.068000000000000005" pos="-6.6613381477509392e-16 3 0.60000000000000009" quat="1.1102230246251565e-16 1.1102230246251565e-16 -0.58778525229247314 -0.80901699437494745"/>
    </body>
  </worldbody>
  <actuator>
    <position name="actuator_position_a0_joint_body_00" class="/" ctrllimited="false" forcelimited="true" ctrlrange="-1000000 1000000" forcerange="-100 100" joint="a0_joint_body_00" kp="0" kv="0"/>
    <velocity name="actuator_velocity_a0_joint_body_00" class="/" ctrllimited="false" forcelimited="true" ctrlrange="-1000000 1000000" forcerange="-100 100" joint="a0_joint_body_00" kv="0"/>
    <motor name="actuator_torque_a0_joint_body_00" class="/" forcelimited="true" forcerange="-100 100" joint="a0_joint_body_00"/>
    <position name="actuator_position_a0_joint_body_01" class="/" ctrllimited="false" forcelimited="true" ctrlrange="-1000000 1000000" forcerange="-100 100" joint="a0_joint_body_01" kp="0" kv="0"/>
    <velocity name="actuator_velocity_a0_joint_body_01" class="/" ctrllimited="false" forcelimited="true" ctrlrange="-1000000 1000000" forcerange="-100 100" joint="a0_joint_body_01" kv="0"/>
    <motor name="actuator_torque_a0_joint_body_01" class="/" forcelimited="true" forcerange="-100 100" joint="a0_joint_body_01"/>
    <position name="actuator_position_a0_joint_body_02" class="/" ctrllimited="false" forcelimited="true" ctrlrange="-1000000 1000000" forcerange="-100 100" joint="a0_joint_body_02" kp="0" kv="0"/>
    <velocity name="actuator_velocity_a0_joint_body_02" class="/" ctrllimited="false" forcelimited="true" ctrlrange="-1000000 1000000" forcerange="-100 100" joint="a0_joint_body_02" kv="0"/>
    <motor name="actuator_torque_a0_joint_body_02" class="/" forcelimited="true" forcerange="-100 100" joint="a0_joint_body_02"/>
    <position name="actuator_position_a0_joint_body_03" class="/" ctrllimited="false" forcelimited="true" ctrlrange="-1000000 1000000" forcerange="-100 100" joint="a0_joint_body_03" kp="0" kv="0"/>
    <velocity name="actuator_velocity_a0_joint_body_03" class="/" ctrllimited="false" forcelimited="true" ctrlrange="-1000000 1000000" forcerange="-100 100" joint="a0_joint_body_03" kv="0"/>
    <motor name="actuator_torque_a0_joint_body_03" class="/" forcelimited="true" forcerange="-100 100" joint="a0_joint_body_03"/>
    <position name="actuator_position_a0_joint_body_04" class="/" ctrllimited="false" forcelimited="true" ctrlrange="-1000000 1000000" forcerange="-100 100" joint="a0_joint_body_04" kp="0" kv="0"/>
    <velocity name="actuator_velocity_a0_joint_body_04" class="/" ctrllimited="false" forcelimited="true" ctrlrange="-1000000 1000000" forcerange="-100 100" joint="a0_joint_body_04" kv="0"/>
    <motor name="actuator_torque_a0_joint_body_04" class="/" forcelimited="true" forcerange="-100 100" joint="a0_joint_body_04"/>
    <position name="actuator_position_a0_joint_body_06" class="/" ctrllimited="false" forcelimited="true" ctrlrange="-1000000 1000000" forcerange="-100 100" joint="a0_joint_body_06" kp="0" kv="0"/>
    <velocity name="actuator_velocity_a0_joint_body_06" class="/" ctrllimited="false" forcelimited="true" ctrlrange="-1000000 1000000" forcerange="-100 100" joint="a0_joint_body_06" kv="0"/>
    <motor name="actuator_torque_a0_joint_body_06" class="/" forcelimited="true" forcerange="-100 100" joint="a0_joint_body_06"/>
    <position name="actuator_position_a0_joint_body_07" class="/" ctrllimited="false" forcelimited="true" ctrlrange="-1000000 1000000" forcerange="-100 100" joint="a0_joint_body_07" kp="0" kv="0"/>
    <velocity name="actuator_velocity_a0_joint_body_07" class="/" ctrllimited="false" forcelimited="true" ctrlrange="-1000000 1000000" forcerange="-100 100" joint="a0_joint_body_07" kv="0"/>
    <motor name="actuator_torque_a0_joint_body_07" class="/" forcelimited="true" forcerange="-100 100" joint="a0_joint_body_07"/>
    <position name="actuator_position_a0_joint_body_08" class="/" ctrllimited="false" forcelimited="true" ctrlrange="-1000000 1000000" forcerange="-100 100" joint="a0_joint_body_08" kp="0" kv="0"/>
    <velocity name="actuator_velocity_a0_joint_body_08" class="/" ctrllimited="false" forcelimited="true" ctrlrange="-1000000 1000000" forcerange="-100 100" joint="a0_joint_body_08" kv="0"/>
    <motor name="actuator_torque_a0_joint_body_08" class="/" forcelimited="true" forcerange="-100 100" joint="a0_joint_body_08"/>
    <position name="actuator_position_a0_joint_leg_0_L_0" class="/" ctrllimited="false" forcelimited="true" ctrlrange="-1000000 1000000" forcerange="-100 100" joint="a0_joint_leg_0_L_0" kp="0" kv="0"/>
    <velocity name="actuator_velocity_a0_joint_leg_0_L_0" class="/" ctrllimited="false" forcelimited="true" ctrlrange="-1000000 1000000" forcerange="-100 100" joint="a0_joint_leg_0_L_0" kv="0"/>
    <motor name="actuator_torque_a0_joint_leg_0_L_0" class="/" forcelimited="true" forcerange="-100 100" joint="a0_joint_leg_0_L_0"/>
    <position name="actuator_position_a0_joint_leg_0_L_1" class="/" ctrllimited="false" forcelimited="true" ctrlrange="-1000000 1000000" forcerange="-100 100" joint="a0_joint_leg_0_L_1" kp="0" kv="0"/>
    <velocity name="actuator_velocity_a0_joint_leg_0_L_1" class="/" ctrllimited="false" forcelimited="true" ctrlrange="-1000000 1000000" forcerange="-100 100" joint="a0_joint_leg_0_L_1" kv="0"/>
    <motor name="actuator_torque_a0_joint_leg_0_L_1" class="/" forcelimited="true" forcerange="-100 100" joint="a0_joint_leg_0_L_1"/>
    <position name="actuator_position_a0_joint_leg_0_R_0" class="/" ctrllimited="false" forcelimited="true" ctrlrange="-1000000 1000000" forcerange="-100 100" joint="a0_joint_leg_0_R_0" kp="0" kv="0"/>
    <velocity name="actuator_velocity_a0_joint_leg_0_R_0" class="/" ctrllimited="false" forcelimited="true" ctrlrange="-1000000 1000000" forcerange="-100 100" joint="a0_joint_leg_0_R_0" kv="0"/>
    <motor name="actuator_torque_a0_joint_leg_0_R_0" class="/" forcelimited="true" forcerange="-100 100" joint="a0_joint_leg_0_R_0"/>
    <position name="actuator_position_a0_joint_leg_0_R_1" class="/" ctrllimited="false" forcelimited="true" ctrlrange="-1000000 1000000" forcerange="-100 100" joint="a0_joint_leg_0_R_1" kp="0" kv="0"/>
    <velocity name="actuator_velocity_a0_joint_leg_0_R_1" class="/" ctrllimited="false" forcelimited="true" ctrlrange="-1000000 1000000" forcerange="-100 100" joint="a0_joint_leg_0_R_1" kv="0"/>
    <motor name="actuator_torque_a0_joint_leg_0_R_1" class="/" forcelimited="true" forcerange="-100 100" joint="a0_joint_leg_0_R_1"/>
    <position name="actuator_position_a0_joint_leg_1_L_0" class="/" ctrllimited="false" forcelimited="true" ctrlrange="-1000000 1000000" forcerange="-100 100" joint="a0_joint_leg_1_L_0" kp="0" kv="0"/>
    <velocity name="actuator_velocity_a0_joint_leg_1_L_0" class="/" ctrllimited="false" forcelimited="true" ctrlrange="-1000000 1000000" forcerange="-100 100" joint="a0_joint_leg_1_L_0" kv="0"/>
    <motor name="actuator_torque_a0_joint_leg_1_L_0" class="/" forcelimited="true" forcerange="-100 100" joint="a0_joint_leg_1_L_0"/>
    <position name="actuator_position_a0_joint_leg_1_L_1" class="/" ctrllimited="false" forcelimited="true" ctrlrange="-1000000 1000000" forcerange="-100 100" joint="a0_joint_leg_1_L_1" kp="0" kv="0"/>
    <velocity name="actuator_velocity_a0_joint_leg_1_L_1" class="/" ctrllimited="false" forcelimited="true" ctrlrange="-1000000 1000000" forcerange="-100 100" joint="a0_joint_leg_1_L_1" kv="0"/>
    <motor name="actuator_torque_a0_joint_leg_1_L_1" class="/" forcelimited="true" forcerange="-100 100" joint="a0_joint_leg_1_L_1"/>
    <position name="actuator_position_a0_joint_leg_1_R_0" class="/" ctrllimited="false" forcelimited="true" ctrlrange="-1000000 1000000" forcerange="-100 100" joint="a0_joint_leg_1_R_0" kp="0" kv="0"/>
    <velocity name="actuator_velocity_a0_joint_leg_1_R_0" class="/" ctrllimited="false" forcelimited="true" ctrlrange="-1000000 1000000" forcerange="-100 100" joint="a0_joint_leg_1_R_0" kv="0"/>
    <motor name="actuator_torque_a0_joint_leg_1_R_0" class="/" forcelimited="true" forcerange="-100 100" joint="a0_joint_leg_1_R_0"/>
    <position name="actuator_position_a0_joint_leg_1_R_1" class="/" ctrllimited="false" forcelimited="true" ctrlrange="-1000000 1000000" forcerange="-100 100" joint="a0_joint_leg_1_R_1" kp="0" kv="0"/>
    <velocity name="actuator_velocity_a0_joint_leg_1_R_1" class="/" ctrllimited="false" forcelimited="true" ctrlrange="-1000000 1000000" forcerange="-100 100" joint="a0_joint_leg_1_R_1" kv="0"/>
    <motor name="actuator_torque_a0_joint_leg_1_R_1" class="/" forcelimited="true" forcerange="-100 100" joint="a0_joint_leg_1_R_1"/>
    <position name="actuator_position_a0_joint_body_05_passive" class="/" ctrllimited="false" forcelimited="true" ctrlrange="-1000000 1000000" forcerange="-100 100" joint="a0_joint_body_05_passive" kp="0" kv="0"/>
    <velocity name="actuator_velocity_a0_joint_body_05_passive" class="/" ctrllimited="false" forcelimited="true" ctrlrange="-1000000 1000000" forcerange="-100 100" joint="a0_joint_body_05_passive" kv="0"/>
    <motor name="actuator_torque_a0_joint_body_05_passive" class="/" forcelimited="true" forcerange="-100 100" joint="a0_joint_body_05_passive"/>
    <position name="actuator_position_a0_joint_body_09_passive" class="/" ctrllimited="false" forcelimited="true" ctrlrange="-1000000 1000000" forcerange="-100 100" joint="a0_joint_body_09_passive" kp="0" kv="0"/>
    <velocity name="actuator_velocity_a0_joint_body_09_passive" class="/" ctrllimited="false" forcelimited="true" ctrlrange="-1000000 1000000" forcerange="-100 100" joint="a0_joint_body_09_passive" kv="0"/>
    <motor name="actuator_torque_a0_joint_body_09_passive" class="/" forcelimited="true" forcerange="-100 100" joint="a0_joint_body_09_passive"/>
  </actuator>
  <sensor>
    <framelinvel name="framelinvel_a0_Polymander_v6.2.1" objtype="body" objname="a0_Polymander_v6.2.1"/>
    <frameangvel name="frameangvel_a0_Polymander_v6.2.1" objtype="body" objname="a0_Polymander_v6.2.1"/>
    <framelinvel name="framelinvel_a0_link_body_00" objtype="body" objname="a0_link_body_00"/>
    <frameangvel name="frameangvel_a0_link_body_00" objtype="body" objname="a0_link_body_00"/>
    <framelinvel name="framelinvel_a0_link_body_01" objtype="body" objname="a0_link_body_01"/>
    <frameangvel name="frameangvel_a0_link_body_01" objtype="body" objname="a0_link_body_01"/>
    <framelinvel name="framelinvel_a0_link_body_02" objtype="body" objname="a0_link_body_02"/>
    <frameangvel name="frameangvel_a0_link_body_02" objtype="body" objname="a0_link_body_02"/>
    <framelinvel name="framelinvel_a0_link_body_03" objtype="body" objname="a0_link_body_03"/>
    <frameangvel name="frameangvel_a0_link_body_03" objtype="body" objname="a0_link_body_03"/>
    <framelinvel name="framelinvel_a0_link_body_04" objtype="body" objname="a0_link_body_04"/>
    <frameangvel name="frameangvel_a0_link_body_04" objtype="body" objname="a0_link_body_04"/>
    <framelinvel name="framelinvel_a0_link_body_05" objtype="body" objname="a0_link_body_05"/>
    <frameangvel name="frameangvel_a0_link_body_05" objtype="body" objname="a0_link_body_05"/>
    <framelinvel name="framelinvel_a0_link_body_06" objtype="body" objname="a0_link_body_06"/>
    <frameangvel name="frameangvel_a0_link_body_06" objtype="body" objname="a0_link_body_06"/>
    <framelinvel name="framelinvel_a0_link_body_07" objtype="body" objname="a0_link_body_07"/>
    <frameangvel name="frameangvel_a0_link_body_07" objtype="body" objname="a0_link_body_07"/>
    <framelinvel name="framelinvel_a0_link_body_08" objtype="body" objname="a0_link_body_08"/>
    <frameangvel name="frameangvel_a0_link_body_08" objtype="body" objname="a0_link_body_08"/>
    <framelinvel name="framelinvel_a0_link_body_09" objtype="body" objname="a0_link_body_09"/>
    <frameangvel name="frameangvel_a0_link_body_09" objtype="body" objname="a0_link_body_09"/>
    <framelinvel name="framelinvel_a0_link_body_10" objtype="body" objname="a0_link_body_10"/>
    <frameangvel name="frameangvel_a0_link_body_10" objtype="body" objname="a0_link_body_10"/>
    <framelinvel name="framelinvel_a0_link_leg_1_L_0" objtype="body" objname="a0_link_leg_1_L_0"/>
    <frameangvel name="frameangvel_a0_link_leg_1_L_0" objtype="body" objname="a0_link_leg_1_L_0"/>
    <framelinvel name="framelinvel_a0_link_leg_1_L_1" objtype="body" objname="a0_link_leg_1_L_1"/>
    <frameangvel name="frameangvel_a0_link_leg_1_L_1" objtype="body" objname="a0_link_leg_1_L_1"/>
    <framelinvel name="framelinvel_a0_link_leg_1_R_0" objtype="body" objname="a0_link_leg_1_R_0"/>
    <frameangvel name="frameangvel_a0_link_leg_1_R_0" objtype="body" objname="a0_link_leg_1_R_0"/>
    <framelinvel name="framelinvel_a0_link_leg_1_R_1" objtype="body" objname="a0_link_leg_1_R_1"/>
    <frameangvel name="frameangvel_a0_link_leg_1_R_1" objtype="body" objname="a0_link_leg_1_R_1"/>
    <framelinvel name="framelinvel_a0_link_leg_0_L_0" objtype="body" objname="a0_link_leg_0_L_0"/>
    <frameangvel name="frameangvel_a0_link_leg_0_L_0" objtype="body" objname="a0_link_leg_0_L_0"/>
    <framelinvel name="framelinvel_a0_link_leg_0_L_1" objtype="body" objname="a0_link_leg_0_L_1"/>
    <frameangvel name="frameangvel_a0_link_leg_0_L_1" objtype="body" objname="a0_link_leg_0_L_1"/>
    <framelinvel name="framelinvel_a0_link_leg_0_R_0" objtype="body" objname="a0_link_leg_0_R_0"/>
    <frameangvel name="frameangvel_a0_link_leg_0_R_0" objtype="body" objname="a0_link_leg_0_R_0"/>
    <framelinvel name="framelinvel_a0_link_leg_0_R_1" objtype="body" objname="a0_link_leg_0_R_1"/>
    <frameangvel name="frameangvel_a0_link_leg_0_R_1" objtype="body" objname="a0_link_leg_0_R_1"/>
    <actuatorfrc name="actuatorfrc_position_a0_joint_body_00" actuator="actuator_position_a0_joint_body_00"/>
    <actuatorfrc name="actuatorfrc_velocity_a0_joint_body_00" actuator="actuator_velocity_a0_joint_body_00"/>
    <actuatorfrc name="actuatorfrc_motor_a0_joint_body_00" actuator="actuator_torque_a0_joint_body_00"/>
    <actuatorfrc name="actuatorfrc_position_a0_joint_body_01" actuator="actuator_position_a0_joint_body_01"/>
    <actuatorfrc name="actuatorfrc_velocity_a0_joint_body_01" actuator="actuator_velocity_a0_joint_body_01"/>
    <actuatorfrc name="actuatorfrc_motor_a0_joint_body_01" actuator="actuator_torque_a0_joint_body_01"/>
    <actuatorfrc name="actuatorfrc_position_a0_joint_body_02" actuator="actuator_position_a0_joint_body_02"/>
    <actuatorfrc name="actuatorfrc_velocity_a0_joint_body_02" actuator="actuator_velocity_a0_joint_body_02"/>
    <actuatorfrc name="actuatorfrc_motor_a0_joint_body_02" actuator="actuator_torque_a0_joint_body_02"/>
    <actuatorfrc name="actuatorfrc_position_a0_joint_body_03" actuator="actuator_position_a0_joint_body_03"/>
    <actuatorfrc name="actuatorfrc_velocity_a0_joint_body_03" actuator="actuator_velocity_a0_joint_body_03"/>
    <actuatorfrc name="actuatorfrc_motor_a0_joint_body_03" actuator="actuator_torque_a0_joint_body_03"/>
    <actuatorfrc name="actuatorfrc_position_a0_joint_body_04" actuator="actuator_position_a0_joint_body_04"/>
    <actuatorfrc name="actuatorfrc_velocity_a0_joint_body_04" actuator="actuator_velocity_a0_joint_body_04"/>
    <actuatorfrc name="actuatorfrc_motor_a0_joint_body_04" actuator="actuator_torque_a0_joint_body_04"/>
    <actuatorfrc name="actuatorfrc_position_a0_joint_body_06" actuator="actuator_position_a0_joint_body_06"/>
    <actuatorfrc name="actuatorfrc_velocity_a0_joint_body_06" actuator="actuator_velocity_a0_joint_body_06"/>
    <actuatorfrc name="actuatorfrc_motor_a0_joint_body_06" actuator="actuator_torque_a0_joint_body_06"/>
    <actuatorfrc name="actuatorfrc_position_a0_joint_body_07" actuator="actuator_position_a0_joint_body_07"/>
    <actuatorfrc name="actuatorfrc_velocity_a0_joint_body_07" actuator="actuator_velocity_a0_joint_body_07"/>
    <actuatorfrc name="actuatorfrc_motor_a0_joint_body_07" actuator="actuator_torque_a0_joint_body_07"/>
    <actuatorfrc name="actuatorfrc_position_a0_joint_body_08" actuator="actuator_position_a0_joint_body_08"/>
    <actuatorfrc name="actuatorfrc_velocity_a0_joint_body_08" actuator="actuator_velocity_a0_joint_body_08"/>
    <actuatorfrc name="actuatorfrc_motor_a0_joint_body_08" actuator="actuator_torque_a0_joint_body_08"/>
    <actuatorfrc name="actuatorfrc_position_a0_joint_leg_0_L_0" actuator="actuator_position_a0_joint_leg_0_L_0"/>
    <actuatorfrc name="actuatorfrc_velocity_a0_joint_leg_0_L_0" actuator="actuator_velocity_a0_joint_leg_0_L_0"/>
    <actuatorfrc name="actuatorfrc_motor_a0_joint_leg_0_L_0" actuator="actuator_torque_a0_joint_leg_0_L_0"/>
    <actuatorfrc name="actuatorfrc_position_a0_joint_leg_0_L_1" actuator="actuator_position_a0_joint_leg_0_L_1"/>
    <actuatorfrc name="actuatorfrc_velocity_a0_joint_leg_0_L_1" actuator="actuator_velocity_a0_joint_leg_0_L_1"/>
    <actuatorfrc name="actuatorfrc_motor_a0_joint_leg_0_L_1" actuator="actuator_torque_a0_joint_leg_0_L_1"/>
    <actuatorfrc name="actuatorfrc_position_a0_joint_leg_0_R_0" actuator="actuator_position_a0_joint_leg_0_R_0"/>
    <actuatorfrc name="actuatorfrc_velocity_a0_joint_leg_0_R_0" actuator="actuator_velocity_a0_joint_leg_0_R_0"/>
    <actuatorfrc name="actuatorfrc_motor_a0_joint_leg_0_R_0" actuator="actuator_torque_a0_joint_leg_0_R_0"/>
    <actuatorfrc name="actuatorfrc_position_a0_joint_leg_0_R_1" actuator="actuator_position_a0_joint_leg_0_R_1"/>
    <actuatorfrc name="actuatorfrc_velocity_a0_joint_leg_0_R_1" actuator="actuator_velocity_a0_joint_leg_0_R_1"/>
    <actuatorfrc name="actuatorfrc_motor_a0_joint_leg_0_R_1" actuator="actuator_torque_a0_joint_leg_0_R_1"/>
    <actuatorfrc name="actuatorfrc_position_a0_joint_leg_1_L_0" actuator="actuator_position_a0_joint_leg_1_L_0"/>
    <actuatorfrc name="actuatorfrc_velocity_a0_joint_leg_1_L_0" actuator="actuator_velocity_a0_joint_leg_1_L_0"/>
    <actuatorfrc name="actuatorfrc_motor_a0_joint_leg_1_L_0" actuator="actuator_torque_a0_joint_leg_1_L_0"/>
    <actuatorfrc name="actuatorfrc_position_a0_joint_leg_1_L_1" actuator="actuator_position_a0_joint_leg_1_L_1"/>
    <actuatorfrc name="actuatorfrc_velocity_a0_joint_leg_1_L_1" actuator="actuator_velocity_a0_joint_leg_1_L_1"/>
    <actuatorfrc name="actuatorfrc_motor_a0_joint_leg_1_L_1" actuator="actuator_torque_a0_joint_leg_1_L_1"/>
    <actuatorfrc name="actuatorfrc_position_a0_joint_leg_1_R_0" actuator="actuator_position_a0_joint_leg_1_R_0"/>
    <actuatorfrc name="actuatorfrc_velocity_a0_joint_leg_1_R_0" actuator="actuator_velocity_a0_joint_leg_1_R_0"/>
    <actuatorfrc name="actuatorfrc_motor_a0_joint_leg_1_R_0" actuator="actuator_torque_a0_joint_leg_1_R_0"/>
    <actuatorfrc name="actuatorfrc_position_a0_joint_leg_1_R_1" actuator="actuator_position_a0_joint_leg_1_R_1"/>
    <actuatorfrc name="actuatorfrc_velocity_a0_joint_leg_1_R_1" actuator="actuator_velocity_a0_joint_leg_1_R_1"/>
    <actuatorfrc name="actuatorfrc_motor_a0_joint_leg_1_R_1" actuator="actuator_torque_a0_joint_leg_1_R_1"/>
    <actuatorfrc name="actuatorfrc_position_a0_joint_body_05_passive" actuator="actuator_position_a0_joint_body_05_passive"/>
    <actuatorfrc name="actuatorfrc_velocity_a0_joint_body_05_passive" actuator="actuator_velocity_a0_joint_body_05_passive"/>
    <actuatorfrc name="actuatorfrc_motor_a0_joint_body_05_passive" actuator="actuator_torque_a0_joint_body_05_passive"/>
    <actuatorfrc name="actuatorfrc_position_a0_joint_body_09_passive" actuator="actuator_position_a0_joint_body_09_passive"/>
    <actuatorfrc name="actuatorfrc_velocity_a0_joint_body_09_passive" actuator="actuator_velocity_a0_joint_body_09_passive"/>
    <actuatorfrc name="actuatorfrc_motor_a0_joint_body_09_passive" actuator="actuator_torque_a0_joint_body_09_passive"/>
  </sensor>
  <keyframe>
    <key name="initial" time="0" qpos="0 0 0.10000000000000001 0.70710678118654757 0 0 0.70710678118654746 0 0 0 0 0 0 0 0 0 0 0 0 0 0 0 0 0 0" qvel="0 0 0 0 0 0 0 0 0 0 0 0 0 0 0 0 0 0 0 0 0 0 0 0"/>
  </keyframe>
</mujoco>
